W0807 12:51:24.601000 22673932490560 torch/distributed/run.py:779] 
W0807 12:51:24.601000 22673932490560 torch/distributed/run.py:779] *****************************************
W0807 12:51:24.601000 22673932490560 torch/distributed/run.py:779] Setting OMP_NUM_THREADS environment variable for each process to be 1 in default, to avoid your system being overloaded, please further tune the variable for optimal performance in your application as needed. 
W0807 12:51:24.601000 22673932490560 torch/distributed/run.py:779] *****************************************
Traceback (most recent call last):
  File "/home/Competition2025/P02/P02U006/ColossalAI/applications/ColossalChat/examples/training_scripts/lora_finetune.py", line 16, in <module>
Traceback (most recent call last):
  File "/home/Competition2025/P02/P02U006/ColossalAI/applications/ColossalChat/examples/training_scripts/lora_finetune.py", line 16, in <module>
    from coati.dataset.loader import RawConversationDataset
ModuleNotFoundError: No module named 'coati'
    from coati.dataset.loader import RawConversationDataset
ModuleNotFoundError: No module named 'coati'
Traceback (most recent call last):
  File "/home/Competition2025/P02/P02U006/ColossalAI/applications/ColossalChat/examples/training_scripts/lora_finetune.py", line 16, in <module>
    from coati.dataset.loader import RawConversationDataset
ModuleNotFoundError: No module named 'coati'
Traceback (most recent call last):
  File "/home/Competition2025/P02/P02U006/ColossalAI/applications/ColossalChat/examples/training_scripts/lora_finetune.py", line 16, in <module>
    from coati.dataset.loader import RawConversationDataset
ModuleNotFoundError: No module named 'coati'
Traceback (most recent call last):
  File "/home/Competition2025/P02/P02U006/ColossalAI/applications/ColossalChat/examples/training_scripts/lora_finetune.py", line 16, in <module>
    from coati.dataset.loader import RawConversationDataset
ModuleNotFoundError: No module named 'coati'
Traceback (most recent call last):
  File "/home/Competition2025/P02/P02U006/ColossalAI/applications/ColossalChat/examples/training_scripts/lora_finetune.py", line 16, in <module>
    from coati.dataset.loader import RawConversationDataset
ModuleNotFoundError: No module named 'coati'
Traceback (most recent call last):
  File "/home/Competition2025/P02/P02U006/ColossalAI/applications/ColossalChat/examples/training_scripts/lora_finetune.py", line 16, in <module>
    from coati.dataset.loader import RawConversationDataset
ModuleNotFoundError: No module named 'coati'
Traceback (most recent call last):
  File "/home/Competition2025/P02/P02U006/ColossalAI/applications/ColossalChat/examples/training_scripts/lora_finetune.py", line 16, in <module>
    from coati.dataset.loader import RawConversationDataset
ModuleNotFoundError: No module named 'coati'
E0807 12:51:34.224000 22673932490560 torch/distributed/elastic/multiprocessing/api.py:833] failed (exitcode: 1) local_rank: 0 (pid: 3365589) of binary: /home/Competition2025/P02/P02U006/miniconda3/envs/deepseeksft310/bin/python3.10
Traceback (most recent call last):
  File "/home/Competition2025/P02/P02U006/miniconda3/envs/deepseeksft310/bin/torchrun", line 8, in <module>
    sys.exit(main())
  File "/home/Competition2025/P02/P02U006/miniconda3/envs/deepseeksft310/lib/python3.10/site-packages/torch/distributed/elastic/multiprocessing/errors/__init__.py", line 348, in wrapper
    return f(*args, **kwargs)
  File "/home/Competition2025/P02/P02U006/miniconda3/envs/deepseeksft310/lib/python3.10/site-packages/torch/distributed/run.py", line 901, in main
    run(args)
  File "/home/Competition2025/P02/P02U006/miniconda3/envs/deepseeksft310/lib/python3.10/site-packages/torch/distributed/run.py", line 892, in run
    elastic_launch(
  File "/home/Competition2025/P02/P02U006/miniconda3/envs/deepseeksft310/lib/python3.10/site-packages/torch/distributed/launcher/api.py", line 133, in __call__
    return launch_agent(self._config, self._entrypoint, list(args))
  File "/home/Competition2025/P02/P02U006/miniconda3/envs/deepseeksft310/lib/python3.10/site-packages/torch/distributed/launcher/api.py", line 264, in launch_agent
    raise ChildFailedError(
torch.distributed.elastic.multiprocessing.errors.ChildFailedError: 
============================================================
/home/Competition2025/P02/P02U006/ColossalAI/applications/ColossalChat/examples/training_scripts/lora_finetune.py FAILED
------------------------------------------------------------
Failures:
[1]:
  time      : 2025-08-07_12:51:34
  host      : osk-gpu91
  rank      : 17 (local_rank: 1)
  exitcode  : 1 (pid: 3365590)
  error_file: <N/A>
  traceback : To enable traceback see: https://pytorch.org/docs/stable/elastic/errors.html
[2]:
  time      : 2025-08-07_12:51:34
  host      : osk-gpu91
  rank      : 18 (local_rank: 2)
  exitcode  : 1 (pid: 3365591)
  error_file: <N/A>
  traceback : To enable traceback see: https://pytorch.org/docs/stable/elastic/errors.html
[3]:
  time      : 2025-08-07_12:51:34
  host      : osk-gpu91
  rank      : 19 (local_rank: 3)
  exitcode  : 1 (pid: 3365592)
  error_file: <N/A>
  traceback : To enable traceback see: https://pytorch.org/docs/stable/elastic/errors.html
[4]:
  time      : 2025-08-07_12:51:34
  host      : osk-gpu91
  rank      : 20 (local_rank: 4)
  exitcode  : 1 (pid: 3365593)
  error_file: <N/A>
  traceback : To enable traceback see: https://pytorch.org/docs/stable/elastic/errors.html
[5]:
  time      : 2025-08-07_12:51:34
  host      : osk-gpu91
  rank      : 21 (local_rank: 5)
  exitcode  : 1 (pid: 3365594)
  error_file: <N/A>
  traceback : To enable traceback see: https://pytorch.org/docs/stable/elastic/errors.html
[6]:
  time      : 2025-08-07_12:51:34
  host      : osk-gpu91
  rank      : 22 (local_rank: 6)
  exitcode  : 1 (pid: 3365595)
  error_file: <N/A>
  traceback : To enable traceback see: https://pytorch.org/docs/stable/elastic/errors.html
[7]:
  time      : 2025-08-07_12:51:34
  host      : osk-gpu91
  rank      : 23 (local_rank: 7)
  exitcode  : 1 (pid: 3365596)
  error_file: <N/A>
  traceback : To enable traceback see: https://pytorch.org/docs/stable/elastic/errors.html
------------------------------------------------------------
Root Cause (first observed failure):
[0]:
  time      : 2025-08-07_12:51:34
  host      : osk-gpu91
  rank      : 16 (local_rank: 0)
  exitcode  : 1 (pid: 3365589)
  error_file: <N/A>
  traceback : To enable traceback see: https://pytorch.org/docs/stable/elastic/errors.html
============================================================
